Workbook

Sheet bobin_list_general
A1: UPLOAD TO SQL | C1: id | D1: bobin_key_code | E1: bobin_identification_code | F1: bobin_size | G1: bobin_type | H1: bobin_current_status | I1: updated_time | J1: SQL | M1: 現状 Đang sử dụng | N1: 組み立てない Chưa sử dụng
A2: {=_xlfn.UNIQUE(J2:J3001)} -> (1, 'A0001_2026_10_03_22_00_00', 'A0001', 'PL7-3', 'Sản xuất', 'Rolled', '2026-10-03 22:00:00'), | C2: 1 | D2: =_xlfn.TEXTJOIN("_",FALSE,E2,"2026_10_03_22_00_00") -> A0001_2026_10_03_22_00_00 | E2: A0001 | F2: {=_xlfn.IFS(LEFT(E2)="A",$L$4,LEFT(E2)="B",$L$2,LEFT(E2)="C",$L$3)} -> PL7-3 | G2: Sản xuất | H2: Rolled | I2: 2026-10-03 22:00:00 | J2: ="(" & C2 & ", '"& D2 & "', '" & E2 & "', '" & F2 & "', '" & G2 & "', '" & H2 & "', '" & I2 & "')," -> (1, 'A0001_2026_10_03_22_00_00', 'A0001', 'PL7-3', 'Sản xuất', 'Rolled', '2026-10-03 22:00:00'), | K2: B | L2: PL4-7 (TU04.TU06) | M2: 350 | N2: 70
A3: (2, 'A0002_2026_10_03_22_00_00', 'A0002', 'PL7-3', 'Sản xuất', 'Rolled', '2026-10-03 22:00:01'), | C3: 2 | D3: =_xlfn.TEXTJOIN("_",FALSE,E3,"2026_10_03_22_00_00") -> A0002_2026_10_03_22_00_00 | E3: A0002 | F3: {=_xlfn.IFS(LEFT(E3)="A",$L$4,LEFT(E3)="B",$L$2,LEFT(E3)="C",$L$3)} -> PL7-3 | G3: Sản xuất | H3: Rolled | I3: 2026-10-03 22:00:01 | J3: ="(" & C3 & ", '"& D3 & "', '" & E3 & "', '" & F3 & "', '" & G3 & "', '" & H3 & "', '" & I3 & "')," -> (2, 'A0002_2026_10_03_22_00_00', 'A0002', 'PL7-3', 'Sản xuất', 'Rolled', '2026-10-03 22:00:01'), | K3: C | L3: PL4-7 (TU08~) | M3: 320 | N3: 160
A4: (3, 'A0003_2026_10_03_22_00_00', 'A0003', 'PL7-3', 'Sản xuất', 'Rolled', '2026-10-03 22:00:02'), | C4: 3 | D4: =_xlfn.TEXTJOIN("_",FALSE,E4,"2026_10_03_22_00_00") -> A0003_2026_10_03_22_00_00 | E4: A0003 | F4: {=_xlfn.IFS(LEFT(E4)="A",$L$4,LEFT(E4)="B",$L$2,LEFT(E4)="C",$L$3)} -> PL7-3 | G4: Sản xuất | H4: Rolled | I4: 2026-10-03 22:00:02 | J4: ="(" & C4 & ", '"& D4 & "', '" & E4 & "', '" & F4 & "', '" & G4 & "', '" & H4 & "', '" & I4 & "')," -> (3, 'A0003_2026_10_03_22_00_00', 'A0003', 'PL7-3', 'Sản xuất', 'Rolled', '2026-10-03 22:00:02'), | K4: A | L4: PL7-3 | M4: 460
A5: (4, 'A0004_2026_10_03_22_00_00', 'A0004', 'PL7-3', 'Sản xuất', 'Rolled', '2026-10-03 22:00:03'), | C5: 4 | D5: =_xlfn.TEXTJOIN("_",FALSE,E5,"2026_10_03_22_00_00") -> A0004_2026_10_03_22_00_00 | E5: A0004 | F5: {=_xlfn.IFS(LEFT(E5)="A",$L$4,LEFT(E5)="B",$L$2,LEFT(E5)="C",$L$3)} -> PL7-3 | G5: Sản xuất | H5: Rolled | I5: 2026-10-03 22:00:03 | J5: ="(" & C5 & ", '"& D5 & "', '" & E5 & "', '" & F5 & "', '" & G5 & "', '" & H5 & "', '" & I5 & "')," -> (4, 'A0004_2026_10_03_22_00_00', 'A0004', 'PL7-3', 'Sản xuất', 'Rolled', '2026-10-03 22:00:03'), | M5: 1130 | N5: 230 | O5: 1360
A6: (5, 'A0005_2026_10_03_22_00_00', 'A0005', 'PL7-3', 'Sản xuất', 'Rolled', '2026-10-03 22:00:04'), | C6: 5 | D6: =_xlfn.TEXTJOIN("_",FALSE,E6,"2026_10_03_22_00_00") -> A0005_2026_10_03_22_00_00 | E6: A0005 | F6: {=_xlfn.IFS(LEFT(E6)="A",$L$4,LEFT(E6)="B",$L$2,LEFT(E6)="C",$L$3)} -> PL7-3 | G6: Sản xuất | H6: Rolled | I6: 2026-10-03 22:00:04 | J6: ="(" & C6 & ", '"& D6 & "', '" & E6 & "', '" & F6 & "', '" & G6 & "', '" & H6 & "', '" & I6 & "')," -> (5, 'A0005_2026_10_03_22_00_00', 'A0005', 'PL7-3', 'Sản xuất', 'Rolled', '2026-10-03 22:00:04'),
A7: (6, 'A0006_2026_10_03_22_00_00', 'A0006', 'PL7-3', 'Sản xuất', 'Rolled', '2026-10-03 22:00:05'), | C7: 6 | D7: =_xlfn.TEXTJOIN("_",FALSE,E7,"2026_10_03_22_00_00") -> A0006_2026_10_03_22_00_00 | E7: A0006 | F7: {=_xlfn.IFS(LEFT(E7)="A",$L$4,LEFT(E7)="B",$L$2,LEFT(E7)="C",$L$3)} -> PL7-3 | G7: Sản xuất | H7: Rolled | I7: 2026-10-03 22:00:05 | J7: ="(" & C7 & ", '"& D7 & "', '" & E7 & "', '" & F7 & "', '" & G7 & "', '" & H7 & "', '" & I7 & "')," -> (6, 'A0006_2026_10_03_22_00_00', 'A0006', 'PL7-3', 'Sản xuất', 'Rolled', '2026-10-03 22:00:05'),
A8: (7, 'A0007_2026_10_03_22_00_00', 'A0007', 'PL7-3', 'Sản xuất', 'Rolled', '2026-10-03 22:00:06'), | C8: 7 | D8: =_xlfn.TEXTJOIN("_",FALSE,E8,"2026_10_03_22_00_00") -> A0007_2026_10_03_22_00_00 | E8: A0007 | F8: {=_xlfn.IFS(LEFT(E8)="A",$L$4,LEFT(E8)="B",$L$2,LEFT(E8)="C",$L$3)} -> PL7-3 | G8: Sản xuất | H8: Rolled | I8: 2026-10-03 22:00:06 | J8: ="(" & C8 & ", '"& D8 & "', '" & E8 & "', '" & F8 & "', '" & G8 & "', '" & H8 & "', '" & I8 & "')," -> (7, 'A0007_2026_10_03_22_00_00', 'A0007', 'PL7-3', 'Sản xuất', 'Rolled', '2026-10-03 22:00:06'),
A9: (8, 'A0008_2026_10_03_22_00_00', 'A0008', 'PL7-3', 'Sản xuất', 'Rolled', '2026-10-03 22:00:07'), | C9: 8 | D9: =_xlfn.TEXTJOIN("_",FALSE,E9,"2026_10_03_22_00_00") -> A0008_2026_10_03_22_00_00 | E9: A0008 | F9: {=_xlfn.IFS(LEFT(E9)="A",$L$4,LEFT(E9)="B",$L$2,LEFT(E9)="C",$L$3)} -> PL7-3 | G9: Sản xuất | H9: Rolled | I9: 2026-10-03 22:00:07 | J9: ="(" & C9 & ", '"& D9 & "', '" & E9 & "', '" & F9 & "', '" & G9 & "', '" & H9 & "', '" & I9 & "')," -> (8, 'A0008_2026_10_03_22_00_00', 'A0008', 'PL7-3', 'Sản xuất', 'Rolled', '2026-10-03 22:00:07'),
A10: (9, 'A0009_2026_10_03_22_00_00', 'A0009', 'PL7-3', 'Sản xuất', 'Rolled', '2026-10-03 22:00:08'), | C10: 9 | D10: =_xlfn.TEXTJOIN("_",FALSE,E10,"2026_10_03_22_00_00") -> A0009_2026_10_03_22_00_00 | E10: A0009 | F10: {=_xlfn.IFS(LEFT(E10)="A",$L$4,LEFT(E10)="B",$L$2,LEFT(E10)="C",$L$3)} -> PL7-3 | G10: Sản xuất | H10: Rolled | I10: 2026-10-03 22:00:08 | J10: ="(" & C10 & ", '"& D10 & "', '" & E10 & "', '" & F10 & "', '" & G10 & "', '" & H10 & "', '" & I10 & "')," -> (9, 'A0009_2026_10_03_22_00_00', 'A0009', 'PL7-3', 'Sản xuất', 'Rolled', '2026-10-03 22:00:08'),
A11: (10, 'A0010_2026_10_03_22_00_00', 'A0010', 'PL7-3', 'Sản xuất', 'Rolled', '2026-10-03 22:00:09'), | C11: 10 | D11: =_xlfn.TEXTJOIN("_",FALSE,E11,"2026_10_03_22_00_00") -> A0010_2026_10_03_22_00_00 | E11: A0010 | F11: {=_xlfn.IFS(LEFT(E11)="A",$L$4,LEFT(E11)="B",$L$2,LEFT(E11)="C",$L$3)} -> PL7-3 | G11: Sản xuất | H11: Rolled | I11: 2026-10-03 22:00:09 | J11: ="(" & C11 & ", '"& D11 & "', '" & E11 & "', '" & F11 & "', '" & G11 & "', '" & H11 & "', '" & I11 & "')," -> (10, 'A0010_2026_10_03_22_00_00', 'A0010', 'PL7-3', 'Sản xuất', 'Rolled', '2026-10-03 22:00:09'),
A12: (11, 'A0011_2026_10_03_22_00_00', 'A0011', 'PL7-3', 'Sản xuất', 'Rolled', '2026-10-03 22:00:10'), | C12: 11 | D12: =_xlfn.TEXTJOIN("_",FALSE,E12,"2026_10_03_22_00_00") -> A0011_2026_10_03_22_00_00 | E12: A0011 | F12: {=_xlfn.IFS(LEFT(E12)="A",$L$4,LEFT(E12)="B",$L$2,LEFT(E12)="C",$L$3)} -> PL7-3 | G12: Sản xuất | H12: Rolled | I12: 2026-10-03 22:00:10 | J12: ="(" & C12 & ", '"& D12 & "', '" & E12 & "', '" & F12 & "', '" & G12 & "', '" & H12 & "', '" & I12 & "')," -> (11, 'A0011_2026_10_03_22_00_00', 'A0011', 'PL7-3', 'Sản xuất', 'Rolled', '2026-10-03 22:00:10'),
A13: (12, 'A0012_2026_10_03_22_00_00', 'A0012', 'PL7-3', 'Sản xuất', 'Rolled', '2026-10-03 22:00:11'), | C13: 12 | D13: =_xlfn.TEXTJOIN("_",FALSE,E13,"2026_10_03_22_00_00") -> A0012_2026_10_03_22_00_00 | E13: A0012 | F13: {=_xlfn.IFS(LEFT(E13)="A",$L$4,LEFT(E13)="B",$L$2,LEFT(E13)="C",$L$3)} -> PL7-3 | G13: Sản xuất | H13: Rolled | I13: 2026-10-03 22:00:11 | J13: ="(" & C13 & ", '"& D13 & "', '" & E13 & "', '" & F13 & "', '" & G13 & "', '" & H13 & "', '" & I13 & "')," -> (12, 'A0012_2026_10_03_22_00_00', 'A0012', 'PL7-3', 'Sản xuất', 'Rolled', '2026-10-03 22:00:11'),
A14: (13, 'A0013_2026_10_03_22_00_00', 'A0013', 'PL7-3', 'Sản xuất', 'Rolled', '2026-10-03 22:00:12'), | C14: 13 | D14: =_xlfn.TEXTJOIN("_",FALSE,E14,"2026_10_03_22_00_00") -> A0013_2026_10_03_22_00_00 | E14: A0013 | F14: {=_xlfn.IFS(LEFT(E14)="A",$L$4,LEFT(E14)="B",$L$2,LEFT(E14)="C",$L$3)} -> PL7-3 | G14: Sản xuất | H14: Rolled | I14: 2026-10-03 22:00:12 | J14: ="(" & C14 & ", '"& D14 & "', '" & E14 & "', '" & F14 & "', '" & G14 & "', '" & H14 & "', '" & I14 & "')," -> (13, 'A0013_2026_10_03_22_00_00', 'A0013', 'PL7-3', 'Sản xuất', 'Rolled', '2026-10-03 22:00:12'),
A15: (14, 'A0014_2026_10_03_22_00_00', 'A0014', 'PL7-3', 'Sản xuất', 'Rolled', '2026-10-03 22:00:13'), | C15: 14 | D15: =_xlfn.TEXTJOIN("_",FALSE,E15,"2026_10_03_22_00_00") -> A0014_2026_10_03_22_00_00 | E15: A0014 | F15: {=_xlfn.IFS(LEFT(E15)="A",$L$4,LEFT(E15)="B",$L$2,LEFT(E15)="C",$L$3)} -> PL7-3 | G15: Sản xuất | H15: Rolled | I15: 2026-10-03 22:00:13 | J15: ="(" & C15 & ", '"& D15 & "', '" & E15 & "', '" & F15 & "', '" & G15 & "', '" & H15 & "', '" & I15 & "')," -> (14, 'A0014_2026_10_03_22_00_00', 'A0014', 'PL7-3', 'Sản xuất', 'Rolled', '2026-10-03 22:00:13'),
A16: (15, 'A0015_2026_10_03_22_00_00', 'A0015', 'PL7-3', 'Sản xuất', 'Rolled', '2026-10-03 22:00:14'), | C16: 15 | D16: =_xlfn.TEXTJOIN("_",FALSE,E16,"2026_10_03_22_00_00") -> A0015_2026_10_03_22_00_00 | E16: A0015 | F16: {=_xlfn.IFS(LEFT(E16)="A",$L$4,LEFT(E16)="B",$L$2,LEFT(E16)="C",$L$3)} -> PL7-3 | G16: Sản xuất | H16: Rolled | I16: 2026-10-03 22:00:14 | J16: ="(" & C16 & ", '"& D16 & "', '" & E16 & "', '" & F16 & "', '" & G16 & "', '" & H16 & "', '" & I16 & "')," -> (15, 'A0015_2026_10_03_22_00_00', 'A0015', 'PL7-3', 'Sản xuất', 'Rolled', '2026-10-03 22:00:14'),
A17: (16, 'A0016_2026_10_03_22_00_00', 'A0016', 'PL7-3', 'Sản xuất', 'Rolled', '2026-10-03 22:00:15'), | C17: 16 | D17: =_xlfn.TEXTJOIN("_",FALSE,E17,"2026_10_03_22_00_00") -> A0016_2026_10_03_22_00_00 | E17: A0016 | F17: {=_xlfn.IFS(LEFT(E17)="A",$L$4,LEFT(E17)="B",$L$2,LEFT(E17)="C",$L$3)} -> PL7-3 | G17: Sản xuất | H17: Rolled | I17: 2026-10-03 22:00:15 | J17: ="(" & C17 & ", '"& D17 & "', '" & E17 & "', '" & F17 & "', '" & G17 & "', '" & H17 & "', '" & I17 & "')," -> (16, 'A0016_2026_10_03_22_00_00', 'A0016', 'PL7-3', 'Sản xuất', 'Rolled', '2026-10-03 22:00:15'),
... A3001: (3000, 'C1000_2026_10_03_22_00_00', 'C1000', 'PL4-7 (TU08~)', 'Sản xuất', 'Rolled', '2026-10-03 22:00:2999'), | C3001: 3000 | D3001: =_xlfn.TEXTJOIN("_",FALSE,E3001,"2026_10_03_22_00_00") -> C1000_2026_10_03_22_00_00 | E3001: C1000 | F3001: {=_xlfn.IFS(LEFT(E3001)="A",$L$4,LEFT(E3001)="B",$L$2,LEFT(E3001)="C",$L$3)} -> PL4-7 (TU08~) | G3001: Sản xuất | H3001: Rolled | I3001: 2026-10-03 22:00:2999 | J3001: ="(" & C3001 & ", '"& D3001 & "', '" & E3001 & "', '" & F3001 & "', '" & G3001 & "', '" & H3001 & "', '" & I3001 & "')," -> (3000, 'C1000_2026_10_03_22_00_00', 'C1000', 'PL4-7 (TU08~)', 'Sản xuất', 'Rolled', '2026-10-03 22:00:2999'),

Sheet bobin_list_detail
A1: UPLOAD TO SQL | B1: Bỏ ngoặc | C1: id | D1: bobin_key_code | E1: bobin_identification_code | F1: bobin_size | G1: bobin_type | H1: extrusion_employee | I1: products | J1: material_lot | K1: print_lot | L1: length_m | M1: shift | N1: extrusion_date | O1: finish_time | P1: bobin_current_status | Q1: visual_inspection | R1: winding_machine | S1: winding_employee | T1: flow_test_result | U1: winding_note | V1: updated_time | X1: id | Y1: bobin_key_code | Z1: bobin_identification_code | AA1: bobin_size | AB1: bobin_type | AC1: extrusion_employee | AD1: extrusion_check | AE1: rack | AF1: products | AG1: material_lot | AH1: print_lot | AI1: length_m | AJ1: shift | AK1: extrusion_date | AL1: finish_time | AM1: bobin_current_status | AN1: visual_inspection | AO1: winding_machine | AP1: winding_employee | AQ1: flow_test_result | AR1: winding_note | AS1: updated_time | AT1: SQL
A2: {=_xlfn.UNIQUE(AT2:AT3001)} -> (1, 'A0001_2026_10_03_22_00_00', 'A0001', 'PL7-3', 'Sản xuất', null, null, null, null, null, 'Chưa cập nhật', 0, 'Ca 1', '2026-10-03', '2026-10-03 22:00:00', 'Rolled', null, 'Chưa cập nhật', null, 'Thất bại', 'Chưa cập nhật', '2026-10-03 22:00:00'), | B2: =MID(A2,2,LEN(A2)-3) -> 1, 'A0001_2026_10_03_22_00_00', 'A0001', 'PL7-3', 'Sản xuất', null, null, null, null, null, 'Chưa cập nhật', 0, 'Ca 1', '2026-10-03', '2026-10-03 22:00:00', 'Rolled', null, 'Chưa cập nhật', null, 'Thất bại', 'Chưa cập nhật', '2026-10-03 22:00:00' | C2: 1 | D2: 'A0001_2026_08_19_15_00_00' | E2: 'A0001' | F2: 'PL7-3' | G2: 'Sản xuất' | H2: null | I2: null | J2: null | K2: 'Chưa cập nhật' | L2: 0 | M2: 'Ca 1' | N2: '2026-08-19' | O2: '2026-08-19 15:00:00' | P2: 'Rolled' | Q2: null | R2: 'Chưa cập nhật' | S2: null | T2: 'Thất bại' | U2: 'Chưa cập nhật' | V2: '2026-08-19 15:00:00' | X2: 1 | Y2: A0001_2026_10_03_22_00_00 | Z2: A0001 | AA2: PL7-3 | AB2: Sản xuất | AC2: null | AD2: null | AE2: null | AF2: null | AG2: null | AH2: Chưa cập nhật | AI2: 0 | AJ2: Ca 1 | AK2: 2026-10-03 | AL2: 2026-10-03 22:00:00 | AM2: Rolled | AN2: null | AO2: Chưa cập nhật | AP2: null | AQ2: Thất bại | AR2: Chưa cập nhật | AS2: 2026-10-03 22:00:00 | AT2: ="(" & X2 & ", '" & Y2 & "', '" & Z2 & "', '" & AA2 & "', '" & AB2 & "', " & AC2 & ", "&AD2&", "&AE2 &", " & AF2 & ", " & AG2 & ", '" & AH2 & "', " & AI2 & ", '" & AJ2 & "', '" & AK2 & "', '" & AL2 & "', '" & AM2 & "', " & AN2 & ", '" & AO2 & "', " & AP2 & ", '" & AQ2 & "', '" & AR2 & "', '" & AS2 & "')," -> (1, 'A0001_2026_10_03_22_00_00', 'A0001', 'PL7-3', 'Sản xuất', null, null, null, null, null, 'Chưa cập nhật', 0, 'Ca 1', '2026-10-03', '2026-10-03 22:00:00', 'Rolled', null, 'Chưa cập nhật', null, 'Thất bại', 'Chưa cập nhật', '2026-10-03 22:00:00'), | AV2: (1, 'A0001_2026_10_03_22_00_00', 'A0001', 'PL7-3', 'Sản xuất', null, null, null, null, null, 'Chưa cập nhật', 0, 'Ca 1', '2026-10-03', '2026-10-03 22:00:00', 'Rolled', null, 'Chưa cập nhật', null,' Thất bại', 'Chưa cập nhật', '2026-10-03 22:00:00'),
A3: (2, 'A0002_2026_10_03_22_00_00', 'A0002', 'PL7-3', 'Sản xuất', null, null, null, null, null, 'Chưa cập nhật', 0, 'Ca 1', '2026-10-03', '2026-10-03 22:00:00', 'Rolled', null, 'Chưa cập nhật', null, 'Thất bại', 'Chưa cập nhật', '2026-10-03 22:00:00'), | B3: =MID(A3,2,LEN(A3)-3) -> 2, 'A0002_2026_10_03_22_00_00', 'A0002', 'PL7-3', 'Sản xuất', null, null, null, null, null, 'Chưa cập nhật', 0, 'Ca 1', '2026-10-03', '2026-10-03 22:00:00', 'Rolled', null, 'Chưa cập nhật', null, 'Thất bại', 'Chưa cập nhật', '2026-10-03 22:00:00' | C3: 2 | D3: 'A0002_2026_08_19_15_00_00' | E3: 'A0002' | F3: 'PL7-3' | G3: 'Sản xuất' | H3: null | I3: null | J3: null | K3: 'Chưa cập nhật' | L3: 0 | M3: 'Ca 2' | N3: '2026-08-19' | O3: '2026-08-19 15:00:00' | P3: 'Rolled' | Q3: null | R3: 'Chưa cập nhật' | S3: null | T3: 'Thất bại' | U3: 'Chưa cập nhật' | V3: '2026-08-19 15:00:00' | X3: 2 | Y3: A0002_2026_10_03_22_00_00 | Z3: A0002 | AA3: PL7-3 | AB3: Sản xuất | AC3: null | AD3: null | AE3: null | AF3: null | AG3: null | AH3: Chưa cập nhật | AI3: 0 | AJ3: Ca 1 | AK3: 2026-10-03 | AL3: 2026-10-03 22:00:00 | AM3: Rolled | AN3: null | AO3: Chưa cập nhật | AP3: null | AQ3: Thất bại | AR3: Chưa cập nhật | AS3: 2026-10-03 22:00:00 | AT3: ="(" & X3 & ", '" & Y3 & "', '" & Z3 & "', '" & AA3 & "', '" & AB3 & "', " & AC3 & ", "&AD3&", "&AE3 &", " & AF3 & ", " & AG3 & ", '" & AH3 & "', " & AI3 & ", '" & AJ3 & "', '" & AK3 & "', '" & AL3 & "', '" & AM3 & "', " & AN3 & ", '" & AO3 & "', " & AP3 & ", '" & AQ3 & "', '" & AR3 & "', '" & AS3 & "')," -> (2, 'A0002_2026_10_03_22_00_00', 'A0002', 'PL7-3', 'Sản xuất', null, null, null, null, null, 'Chưa cập nhật', 0, 'Ca 1', '2026-10-03', '2026-10-03 22:00:00', 'Rolled', null, 'Chưa cập nhật', null, 'Thất bại', 'Chưa cập nhật', '2026-10-03 22:00:00'),
A4: (3, 'A0003_2026_10_03_22_00_00', 'A0003', 'PL7-3', 'Sản xuất', null, null, null, null, null, 'Chưa cập nhật', 0, 'Ca 1', '2026-10-03', '2026-10-03 22:00:00', 'Rolled', null, 'Chưa cập nhật', null, 'Thất bại', 'Chưa cập nhật', '2026-10-03 22:00:00'), | B4: =MID(A4,2,LEN(A4)-3) -> 3, 'A0003_2026_10_03_22_00_00', 'A0003', 'PL7-3', 'Sản xuất', null, null, null, null, null, 'Chưa cập nhật', 0, 'Ca 1', '2026-10-03', '2026-10-03 22:00:00', 'Rolled', null, 'Chưa cập nhật', null, 'Thất bại', 'Chưa cập nhật', '2026-10-03 22:00:00' | C4: 3 | D4: 'A0003_2026_08_19_15_00_00' | E4: 'A0003' | F4: 'PL7-3' | G4: 'Sản xuất' | H4: null | I4: null | J4: null | K4: 'Chưa cập nhật' | L4: 0 | M4: 'Ca 3' | N4: '2026-08-19' | O4: '2026-08-19 15:00:00' | P4: 'Rolled' | Q4: null | R4: 'Chưa cập nhật' | S4: null | T4: 'Thất bại' | U4: 'Chưa cập nhật' | V4: '2026-08-19 15:00:00' | X4: 3 | Y4: A0003_2026_10_03_22_00_00 | Z4: A0003 | AA4: PL7-3 | AB4: Sản xuất | AC4: null | AD4: null | AE4: null | AF4: null | AG4: null | AH4: Chưa cập nhật | AI4: 0 | AJ4: Ca 1 | AK4: 2026-10-03 | AL4: 2026-10-03 22:00:00 | AM4: Rolled | AN4: null | AO4: Chưa cập nhật | AP4: null | AQ4: Thất bại | AR4: Chưa cập nhật | AS4: 2026-10-03 22:00:00 | AT4: ="(" & X4 & ", '" & Y4 & "', '" & Z4 & "', '" & AA4 & "', '" & AB4 & "', " & AC4 & ", "&AD4&", "&AE4 &", " & AF4 & ", " & AG4 & ", '" & AH4 & "', " & AI4 & ", '" & AJ4 & "', '" & AK4 & "', '" & AL4 & "', '" & AM4 & "', " & AN4 & ", '" & AO4 & "', " & AP4 & ", '" & AQ4 & "', '" & AR4 & "', '" & AS4 & "')," -> (3, 'A0003_2026_10_03_22_00_00', 'A0003', 'PL7-3', 'Sản xuất', null, null, null, null, null, 'Chưa cập nhật', 0, 'Ca 1', '2026-10-03', '2026-10-03 22:00:00', 'Rolled', null, 'Chưa cập nhật', null, 'Thất bại', 'Chưa cập nhật', '2026-10-03 22:00:00'),
A5: (4, 'A0004_2026_10_03_22_00_00', 'A0004', 'PL7-3', 'Sản xuất', null, null, null, null, null, 'Chưa cập nhật', 0, 'Ca 1', '2026-10-03', '2026-10-03 22:00:00', 'Rolled', null, 'Chưa cập nhật', null, 'Thất bại', 'Chưa cập nhật', '2026-10-03 22:00:00'), | B5: =MID(A5,2,LEN(A5)-3) -> 4, 'A0004_2026_10_03_22_00_00', 'A0004', 'PL7-3', 'Sản xuất', null, null, null, null, null, 'Chưa cập nhật', 0, 'Ca 1', '2026-10-03', '2026-10-03 22:00:00', 'Rolled', null, 'Chưa cập nhật', null, 'Thất bại', 'Chưa cập nhật', '2026-10-03 22:00:00' | C5: 4 | D5: 'A0004_2026_08_19_15_00_00' | E5: 'A0004' | F5: 'PL7-3' | G5: 'Sản xuất' | H5: null | I5: null | J5: null | K5: 'Chưa cập nhật' | L5: 0 | M5: 'Ca 4' | N5: '2026-08-19' | O5: '2026-08-19 15:00:00' | P5: 'Rolled' | Q5: null | R5: 'Chưa cập nhật' | S5: null | T5: 'Thất bại' | U5: 'Chưa cập nhật' | V5: '2026-08-19 15:00:00' | X5: 4 | Y5: A0004_2026_10_03_22_00_00 | Z5: A0004 | AA5: PL7-3 | AB5: Sản xuất | AC5: null | AD5: null | AE5: null | AF5: null | AG5: null | AH5: Chưa cập nhật | AI5: 0 | AJ5: Ca 1 | AK5: 2026-10-03 | AL5: 2026-10-03 22:00:00 | AM5: Rolled | AN5: null | AO5: Chưa cập nhật | AP5: null | AQ5: Thất bại | AR5: Chưa cập nhật | AS5: 2026-10-03 22:00:00 | AT5: ="(" & X5 & ", '" & Y5 & "', '" & Z5 & "', '" & AA5 & "', '" & AB5 & "', " & AC5 & ", "&AD5&", "&AE5 &", " & AF5 & ", " & AG5 & ", '" & AH5 & "', " & AI5 & ", '" & AJ5 & "', '" & AK5 & "', '" & AL5 & "', '" & AM5 & "', " & AN5 & ", '" & AO5 & "', " & AP5 & ", '" & AQ5 & "', '" & AR5 & "', '" & AS5 & "')," -> (4, 'A0004_2026_10_03_22_00_00', 'A0004', 'PL7-3', 'Sản xuất', null, null, null, null, null, 'Chưa cập nhật', 0, 'Ca 1', '2026-10-03', '2026-10-03 22:00:00', 'Rolled', null, 'Chưa cập nhật', null, 'Thất bại', 'Chưa cập nhật', '2026-10-03 22:00:00'),
A6: (5, 'A0005_2026_10_03_22_00_00', 'A0005', 'PL7-3', 'Sản xuất', null, null, null, null, null, 'Chưa cập nhật', 0, 'Ca 1', '2026-10-03', '2026-10-03 22:00:00', 'Rolled', null, 'Chưa cập nhật', null, 'Thất bại', 'Chưa cập nhật', '2026-10-03 22:00:00'), | B6: =MID(A6,2,LEN(A6)-3) -> 5, 'A0005_2026_10_03_22_00_00', 'A0005', 'PL7-3', 'Sản xuất', null, null, null, null, null, 'Chưa cập nhật', 0, 'Ca 1', '2026-10-03', '2026-10-03 22:00:00', 'Rolled', null, 'Chưa cập nhật', null, 'Thất bại', 'Chưa cập nhật', '2026-10-03 22:00:00' | C6: 5 | D6: 'A0005_2026_08_19_15_00_00' | E6: 'A0005' | F6: 'PL7-3' | G6: 'Sản xuất' | H6: null | I6: null | J6: null | K6: 'Chưa cập nhật' | L6: 0 | M6: 'Ca 5' | N6: '2026-08-19' | O6: '2026-08-19 15:00:00' | P6: 'Rolled' | Q6: null | R6: 'Chưa cập nhật' | S6: null | T6: 'Thất bại' | U6: 'Chưa cập nhật' | V6: '2026-08-19 15:00:00' | X6: 5 | Y6: A0005_2026_10_03_22_00_00 | Z6: A0005 | AA6: PL7-3 | AB6: Sản xuất | AC6: null | AD6: null | AE6: null | AF6: null | AG6: null | AH6: Chưa cập nhật | AI6: 0 | AJ6: Ca 1 | AK6: 2026-10-03 | AL6: 2026-10-03 22:00:00 | AM6: Rolled | AN6: null | AO6: Chưa cập nhật | AP6: null | AQ6: Thất bại | AR6: Chưa cập nhật | AS6: 2026-10-03 22:00:00 | AT6: ="(" & X6 & ", '" & Y6 & "', '" & Z6 & "', '" & AA6 & "', '" & AB6 & "', " & AC6 & ", "&AD6&", "&AE6 &", " & AF6 & ", " & AG6 & ", '" & AH6 & "', " & AI6 & ", '" & AJ6 & "', '" & AK6 & "', '" & AL6 & "', '" & AM6 & "', " & AN6 & ", '" & AO6 & "', " & AP6 & ", '" & AQ6 & "', '" & AR6 & "', '" & AS6 & "')," -> (5, 'A0005_2026_10_03_22_00_00', 'A0005', 'PL7-3', 'Sản xuất', null, null, null, null, null, 'Chưa cập nhật', 0, 'Ca 1', '2026-10-03', '2026-10-03 22:00:00', 'Rolled', null, 'Chưa cập nhật', null, 'Thất bại', 'Chưa cập nhật', '2026-10-03 22:00:00'),
A7: (6, 'A0006_2026_10_03_22_00_00', 'A0006', 'PL7-3', 'Sản xuất', null, null, null, null, null, 'Chưa cập nhật', 0, 'Ca 1', '2026-10-03', '2026-10-03 22:00:00', 'Rolled', null, 'Chưa cập nhật', null, 'Thất bại', 'Chưa cập nhật', '2026-10-03 22:00:00'), | B7: =MID(A7,2,LEN(A7)-3) -> 6, 'A0006_2026_10_03_22_00_00', 'A0006', 'PL7-3', 'Sản xuất', null, null, null, null, null, 'Chưa cập nhật', 0, 'Ca 1', '2026-10-03', '2026-10-03 22:00:00', 'Rolled', null, 'Chưa cập nhật', null, 'Thất bại', 'Chưa cập nhật', '2026-10-03 22:00:00' | C7: 6 | D7: 'A0006_2026_08_19_15_00_00' | E7: 'A0006' | F7: 'PL7-3' | G7: 'Sản xuất' | H7: null | I7: null | J7: null | K7: 'Chưa cập nhật' | L7: 0 | M7: 'Ca 6' | N7: '2026-08-19' | O7: '2026-08-19 15:00:00' | P7: 'Rolled' | Q7: null | R7: 'Chưa cập nhật' | S7: null | T7: 'Thất bại' | U7: 'Chưa cập nhật' | V7: '2026-08-19 15:00:00' | X7: 6 | Y7: A0006_2026_10_03_22_00_00 | Z7: A0006 | AA7: PL7-3 | AB7: Sản xuất | AC7: null | AD7: null | AE7: null | AF7: null | AG7: null | AH7: Chưa cập nhật | AI7: 0 | AJ7: Ca 1 | AK7: 2026-10-03 | AL7: 2026-10-03 22:00:00 | AM7: Rolled | AN7: null | AO7: Chưa cập nhật | AP7: null | AQ7: Thất bại | AR7: Chưa cập nhật | AS7: 2026-10-03 22:00:00 | AT7: ="(" & X7 & ", '" & Y7 & "', '" & Z7 & "', '" & AA7 & "', '" & AB7 & "', " & AC7 & ", "&AD7&", "&AE7 &", " & AF7 & ", " & AG7 & ", '" & AH7 & "', " & AI7 & ", '" & AJ7 & "', '" & AK7 & "', '" & AL7 & "', '" & AM7 & "', " & AN7 & ", '" & AO7 & "', " & AP7 & ", '" & AQ7 & "', '" & AR7 & "', '" & AS7 & "')," -> (6, 'A0006_2026_10_03_22_00_00', 'A0006', 'PL7-3', 'Sản xuất', null, null, null, null, null, 'Chưa cập nhật', 0, 'Ca 1', '2026-10-03', '2026-10-03 22:00:00', 'Rolled', null, 'Chưa cập nhật', null, 'Thất bại', 'Chưa cập nhật', '2026-10-03 22:00:00'),
A8: (7, 'A0007_2026_10_03_22_00_00', 'A0007', 'PL7-3', 'Sản xuất', null, null, null, null, null, 'Chưa cập nhật', 0, 'Ca 1', '2026-10-03', '2026-10-03 22:00:00', 'Rolled', null, 'Chưa cập nhật', null, 'Thất bại', 'Chưa cập nhật', '2026-10-03 22:00:00'), | B8: =MID(A8,2,LEN(A8)-3) -> 7, 'A0007_2026_10_03_22_00_00', 'A0007', 'PL7-3', 'Sản xuất', null, null, null, null, null, 'Chưa cập nhật', 0, 'Ca 1', '2026-10-03', '2026-10-03 22:00:00', 'Rolled', null, 'Chưa cập nhật', null, 'Thất bại', 'Chưa cập nhật', '2026-10-03 22:00:00' | C8: 7 | D8: 'A0007_2026_08_19_15_00_00' | E8: 'A0007' | F8: 'PL7-3' | G8: 'Sản xuất' | H8: null | I8: null | J8: null | K8: 'Chưa cập nhật' | L8: 0 | M8: 'Ca 7' | N8: '2026-08-19' | O8: '2026-08-19 15:00:00' | P8: 'Rolled' | Q8: null | R8: 'Chưa cập nhật' | S8: null | T8: 'Thất bại' | U8: 'Chưa cập nhật' | V8: '2026-08-19 15:00:00' | X8: 7 | Y8: A0007_2026_10_03_22_00_00 | Z8: A0007 | AA8: PL7-3 | AB8: Sản xuất | AC8: null | AD8: null | AE8: null | AF8: null | AG8: null | AH8: Chưa cập nhật | AI8: 0 | AJ8: Ca 1 | AK8: 2026-10-03 | AL8: 2026-10-03 22:00:00 | AM8: Rolled | AN8: null | AO8: Chưa cập nhật | AP8: null | AQ8: Thất bại | AR8: Chưa cập nhật | AS8: 2026-10-03 22:00:00 | AT8: ="(" & X8 & ", '" & Y8 & "', '" & Z8 & "', '" & AA8 & "', '" & AB8 & "', " & AC8 & ", "&AD8&", "&AE8 &", " & AF8 & ", " & AG8 & ", '" & AH8 & "', " & AI8 & ", '" & AJ8 & "', '" & AK8 & "', '" & AL8 & "', '" & AM8 & "', " & AN8 & ", '" & AO8 & "', " & AP8 & ", '" & AQ8 & "', '" & AR8 & "', '" & AS8 & "')," -> (7, 'A0007_2026_10_03_22_00_00', 'A0007', 'PL7-3', 'Sản xuất', null, null, null, null, null, 'Chưa cập nhật', 0, 'Ca 1', '2026-10-03', '2026-10-03 22:00:00', 'Rolled', null, 'Chưa cập nhật', null, 'Thất bại', 'Chưa cập nhật', '2026-10-03 22:00:00'),
A9: (8, 'A0008_2026_10_03_22_00_00', 'A0008', 'PL7-3', 'Sản xuất', null, null, null, null, null, 'Chưa cập nhật', 0, 'Ca 1', '2026-10-03', '2026-10-03 22:00:00', 'Rolled', null, 'Chưa cập nhật', null, 'Thất bại', 'Chưa cập nhật', '2026-10-03 22:00:00'), | B9: =MID(A9,2,LEN(A9)-3) -> 8, 'A0008_2026_10_03_22_00_00', 'A0008', 'PL7-3', 'Sản xuất', null, null, null, null, null, 'Chưa cập nhật', 0, 'Ca 1', '2026-10-03', '2026-10-03 22:00:00', 'Rolled', null, 'Chưa cập nhật', null, 'Thất bại', 'Chưa cập nhật', '2026-10-03 22:00:00' | C9: 8 | D9: 'A0008_2026_08_19_15_00_00' | E9: 'A0008' | F9: 'PL7-3' | G9: 'Sản xuất' | H9: null | I9: null | J9: null | K9: 'Chưa cập nhật' | L9: 0 | M9: 'Ca 8' | N9: '2026-08-19' | O9: '2026-08-19 15:00:00' | P9: 'Rolled' | Q9: null | R9: 'Chưa cập nhật' | S9: null | T9: 'Thất bại' | U9: 'Chưa cập nhật' | V9: '2026-08-19 15:00:00' | X9: 8 | Y9: A0008_2026_10_03_22_00_00 | Z9: A0008 | AA9: PL7-3 | AB9: Sản xuất | AC9: null | AD9: null | AE9: null | AF9: null | AG9: null | AH9: Chưa cập nhật | AI9: 0 | AJ9: Ca 1 | AK9: 2026-10-03 | AL9: 2026-10-03 22:00:00 | AM9: Rolled | AN9: null | AO9: Chưa cập nhật | AP9: null | AQ9: Thất bại | AR9: Chưa cập nhật | AS9: 2026-10-03 22:00:00 | AT9: ="(" & X9 & ", '" & Y9 & "', '" & Z9 & "', '" & AA9 & "', '" & AB9 & "', " & AC9 & ", "&AD9&", "&AE9 &", " & AF9 & ", " & AG9 & ", '" & AH9 & "', " & AI9 & ", '" & AJ9 & "', '" & AK9 & "', '" & AL9 & "', '" & AM9 & "', " & AN9 & ", '" & AO9 & "', " & AP9 & ", '" & AQ9 & "', '" & AR9 & "', '" & AS9 & "')," -> (8, 'A0008_2026_10_03_22_00_00', 'A0008', 'PL7-3', 'Sản xuất', null, null, null, null, null, 'Chưa cập nhật', 0, 'Ca 1', '2026-10-03', '2026-10-03 22:00:00', 'Rolled', null, 'Chưa cập nhật', null, 'Thất bại', 'Chưa cập nhật', '2026-10-03 22:00:00'),
A10: (9, 'A0009_2026_10_03_22_00_00', 'A0009', 'PL7-3', 'Sản xuất', null, null, null, null, null, 'Chưa cập nhật', 0, 'Ca 1', '2026-10-03', '2026-10-03 22:00:00', 'Rolled', null, 'Chưa cập nhật', null, 'Thất bại', 'Chưa cập nhật', '2026-10-03 22:00:00'), | B10: =MID(A10,2,LEN(A10)-3) -> 9, 'A0009_2026_10_03_22_00_00', 'A0009', 'PL7-3', 'Sản xuất', null, null, null, null, null, 'Chưa cập nhật', 0, 'Ca 1', '2026-10-03', '2026-10-03 22:00:00', 'Rolled', null, 'Chưa cập nhật', null, 'Thất bại', 'Chưa cập nhật', '2026-10-03 22:00:00' | C10: 9 | D10: 'A0009_2026_08_19_15_00_00' | E10: 'A0009' | F10: 'PL7-3' | G10: 'Sản xuất' | H10: null | I10: null | J10: null | K10: 'Chưa cập nhật' | L10: 0 | M10: 'Ca 9' | N10: '2026-08-19' | O10: '2026-08-19 15:00:00' | P10: 'Rolled' | Q10: null | R10: 'Chưa cập nhật' | S10: null | T10: 'Thất bại' | U10: 'Chưa cập nhật' | V10: '2026-08-19 15:00:00' | X10: 9 | Y10: A0009_2026_10_03_22_00_00 | Z10: A0009 | AA10: PL7-3 | AB10: Sản xuất | AC10: null | AD10: null | AE10: null | AF10: null | AG10: null | AH10: Chưa cập nhật | AI10: 0 | AJ10: Ca 1 | AK10: 2026-10-03 | AL10: 2026-10-03 22:00:00 | AM10: Rolled | AN10: null | AO10: Chưa cập nhật | AP10: null | AQ10: Thất bại | AR10: Chưa cập nhật | AS10: 2026-10-03 22:00:00 | AT10: ="(" & X10 & ", '" & Y10 & "', '" & Z10 & "', '" & AA10 & "', '" & AB10 & "', " & AC10 & ", "&AD10&", "&AE10 &", " & AF10 & ", " & AG10 & ", '" & AH10 & "', " & AI10 & ", '" & AJ10 & "', '" & AK10 & "', '" & AL10 & "', '" & AM10 & "', " & AN10 & ", '" & AO10 & "', " & AP10 & ", '" & AQ10 & "', '" & AR10 & "', '" & AS10 & "')," -> (9, 'A0009_2026_10_03_22_00_00', 'A0009', 'PL7-3', 'Sản xuất', null, null, null, null, null, 'Chưa cập nhật', 0, 'Ca 1', '2026-10-03', '2026-10-03 22:00:00', 'Rolled', null, 'Chưa cập nhật', null, 'Thất bại', 'Chưa cập nhật', '2026-10-03 22:00:00'),
A11: (10, 'A0010_2026_10_03_22_00_00', 'A0010', 'PL7-3', 'Sản xuất', null, null, null, null, null, 'Chưa cập nhật', 0, 'Ca 1', '2026-10-03', '2026-10-03 22:00:00', 'Rolled', null, 'Chưa cập nhật', null, 'Thất bại', 'Chưa cập nhật', '2026-10-03 22:00:00'), | B11: =MID(A11,2,LEN(A11)-3) -> 10, 'A0010_2026_10_03_22_00_00', 'A0010', 'PL7-3', 'Sản xuất', null, null, null, null, null, 'Chưa cập nhật', 0, 'Ca 1', '2026-10-03', '2026-10-03 22:00:00', 'Rolled', null, 'Chưa cập nhật', null, 'Thất bại', 'Chưa cập nhật', '2026-10-03 22:00:00' | C11: 10 | D11: 'A0010_2026_08_19_15_00_00' | E11: 'A0010' | F11: 'PL7-3' | G11: 'Sản xuất' | H11: null | I11: null | J11: null | K11: 'Chưa cập nhật' | L11: 0 | M11: 'Ca 10' | N11: '2026-08-19' | O11: '2026-08-19 15:00:00' | P11: 'Rolled' | Q11: null | R11: 'Chưa cập nhật' | S11: null | T11: 'Thất bại' | U11: 'Chưa cập nhật' | V11: '2026-08-19 15:00:00' | X11: 10 | Y11: A0010_2026_10_03_22_00_00 | Z11: A0010 | AA11: PL7-3 | AB11: Sản xuất | AC11: null | AD11: null | AE11: null | AF11: null | AG11: null | AH11: Chưa cập nhật | AI11: 0 | AJ11: Ca 1 | AK11: 2026-10-03 | AL11: 2026-10-03 22:00:00 | AM11: Rolled | AN11: null | AO11: Chưa cập nhật | AP11: null | AQ11: Thất bại | AR11: Chưa cập nhật | AS11: 2026-10-03 22:00:00 | AT11: ="(" & X11 & ", '" & Y11 & "', '" & Z11 & "', '" & AA11 & "', '" & AB11 & "', " & AC11 & ", "&AD11&", "&AE11 &", " & AF11 & ", " & AG11 & ", '" & AH11 & "', " & AI11 & ", '" & AJ11 & "', '" & AK11 & "', '" & AL11 & "', '" & AM11 & "', " & AN11 & ", '" & AO11 & "', " & AP11 & ", '" & AQ11 & "', '" & AR11 & "', '" & AS11 & "')," -> (10, 'A0010_2026_10_03_22_00_00', 'A0010', 'PL7-3', 'Sản xuất', null, null, null, null, null, 'Chưa cập nhật', 0, 'Ca 1', '2026-10-03', '2026-10-03 22:00:00', 'Rolled', null, 'Chưa cập nhật', null, 'Thất bại', 'Chưa cập nhật', '2026-10-03 22:00:00'),
A12: (11, 'A0011_2026_10_03_22_00_00', 'A0011', 'PL7-3', 'Sản xuất', null, null, null, null, null, 'Chưa cập nhật', 0, 'Ca 1', '2026-10-03', '2026-10-03 22:00:00', 'Rolled', null, 'Chưa cập nhật', null, 'Thất bại', 'Chưa cập nhật', '2026-10-03 22:00:00'), | B12: =MID(A12,2,LEN(A12)-3) -> 11, 'A0011_2026_10_03_22_00_00', 'A0011', 'PL7-3', 'Sản xuất', null, null, null, null, null, 'Chưa cập nhật', 0, 'Ca 1', '2026-10-03', '2026-10-03 22:00:00', 'Rolled', null, 'Chưa cập nhật', null, 'Thất bại', 'Chưa cập nhật', '2026-10-03 22:00:00' | C12: 11 | D12: 'A0011_2026_08_19_15_00_00' | E12: 'A0011' | F12: 'PL7-3' | G12: 'Sản xuất' | H12: null | I12: null | J12: null | K12: 'Chưa cập nhật' | L12: 0 | M12: 'Ca 11' | N12: '2026-08-19' | O12: '2026-08-19 15:00:00' | P12: 'Rolled' | Q12: null | R12: 'Chưa cập nhật' | S12: null | T12: 'Thất bại' | U12: 'Chưa cập nhật' | V12: '2026-08-19 15:00:00' | X12: 11 | Y12: A0011_2026_10_03_22_00_00 | Z12: A0011 | AA12: PL7-3 | AB12: Sản xuất | AC12: null | AD12: null | AE12: null | AF12: null | AG12: null | AH12: Chưa cập nhật | AI12: 0 | AJ12: Ca 1 | AK12: 2026-10-03 | AL12: 2026-10-03 22:00:00 | AM12: Rolled | AN12: null | AO12: Chưa cập nhật | AP12: null | AQ12: Thất bại | AR12: Chưa cập nhật | AS12: 2026-10-03 22:00:00 | AT12: ="(" & X12 & ", '" & Y12 & "', '" & Z12 & "', '" & AA12 & "', '" & AB12 & "', " & AC12 & ", "&AD12&", "&AE12 &", " & AF12 & ", " & AG12 & ", '" & AH12 & "', " & AI12 & ", '" & AJ12 & "', '" & AK12 & "', '" & AL12 & "', '" & AM12 & "', " & AN12 & ", '" & AO12 & "', " & AP12 & ", '" & AQ12 & "', '" & AR12 & "', '" & AS12 & "')," -> (11, 'A0011_2026_10_03_22_00_00', 'A0011', 'PL7-3', 'Sản xuất', null, null, null, null, null, 'Chưa cập nhật', 0, 'Ca 1', '2026-10-03', '2026-10-03 22:00:00', 'Rolled', null, 'Chưa cập nhật', null, 'Thất bại', 'Chưa cập nhật', '2026-10-03 22:00:00'),
A13: (12, 'A0012_2026_10_03_22_00_00', 'A0012', 'PL7-3', 'Sản xuất', null, null, null, null, null, 'Chưa cập nhật', 0, 'Ca 1', '2026-10-03', '2026-10-03 22:00:00', 'Rolled', null, 'Chưa cập nhật', null, 'Thất bại', 'Chưa cập nhật', '2026-10-03 22:00:00'), | B13: =MID(A13,2,LEN(A13)-3) -> 12, 'A0012_2026_10_03_22_00_00', 'A0012', 'PL7-3', 'Sản xuất', null, null, null, null, null, 'Chưa cập nhật', 0, 'Ca 1', '2026-10-03', '2026-10-03 22:00:00', 'Rolled', null, 'Chưa cập nhật', null, 'Thất bại', 'Chưa cập nhật', '2026-10-03 22:00:00' | C13: 12 | D13: 'A0012_2026_08_19_15_00_00' | E13: 'A0012' | F13: 'PL7-3' | G13: 'Sản xuất' | H13: null | I13: null | J13: null | K13: 'Chưa cập nhật' | L13: 0 | M13: 'Ca 12' | N13: '2026-08-19' | O13: '2026-08-19 15:00:00' | P13: 'Rolled' | Q13: null | R13: 'Chưa cập nhật' | S13: null | T13: 'Thất bại' | U13: 'Chưa cập nhật' | V13: '2026-08-19 15:00:00' | X13: 12 | Y13: A0012_2026_10_03_22_00_00 | Z13: A0012 | AA13: PL7-3 | AB13: Sản xuất | AC13: null | AD13: null | AE13: null | AF13: null | AG13: null | AH13: Chưa cập nhật | AI13: 0 | AJ13: Ca 1 | AK13: 2026-10-03 | AL13: 2026-10-03 22:00:00 | AM13: Rolled | AN13: null | AO13: Chưa cập nhật | AP13: null | AQ13: Thất bại | AR13: Chưa cập nhật | AS13: 2026-10-03 22:00:00 | AT13: ="(" & X13 & ", '" & Y13 & "', '" & Z13 & "', '" & AA13 & "', '" & AB13 & "', " & AC13 & ", "&AD13&", "&AE13 &", " & AF13 & ", " & AG13 & ", '" & AH13 & "', " & AI13 & ", '" & AJ13 & "', '" & AK13 & "', '" & AL13 & "', '" & AM13 & "', " & AN13 & ", '" & AO13 & "', " & AP13 & ", '" & AQ13 & "', '" & AR13 & "', '" & AS13 & "')," -> (12, 'A0012_2026_10_03_22_00_00', 'A0012', 'PL7-3', 'Sản xuất', null, null, null, null, null, 'Chưa cập nhật', 0, 'Ca 1', '2026-10-03', '2026-10-03 22:00:00', 'Rolled', null, 'Chưa cập nhật', null, 'Thất bại', 'Chưa cập nhật', '2026-10-03 22:00:00'),
A14: (13, 'A0013_2026_10_03_22_00_00', 'A0013', 'PL7-3', 'Sản xuất', null, null, null, null, null, 'Chưa cập nhật', 0, 'Ca 1', '2026-10-03', '2026-10-03 22:00:00', 'Rolled', null, 'Chưa cập nhật', null, 'Thất bại', 'Chưa cập nhật', '2026-10-03 22:00:00'), | B14: =MID(A14,2,LEN(A14)-3) -> 13, 'A0013_2026_10_03_22_00_00', 'A0013', 'PL7-3', 'Sản xuất', null, null, null, null, null, 'Chưa cập nhật', 0, 'Ca 1', '2026-10-03', '2026-10-03 22:00:00', 'Rolled', null, 'Chưa cập nhật', null, 'Thất bại', 'Chưa cập nhật', '2026-10-03 22:00:00' | C14: 13 | D14: 'A0013_2026_08_19_15_00_00' | E14: 'A0013' | F14: 'PL7-3' | G14: 'Sản xuất' | H14: null | I14: null | J14: null | K14: 'Chưa cập nhật' | L14: 0 | M14: 'Ca 13' | N14: '2026-08-19' | O14: '2026-08-19 15:00:00' | P14: 'Rolled' | Q14: null | R14: 'Chưa cập nhật' | S14: null | T14: 'Thất bại' | U14: 'Chưa cập nhật' | V14: '2026-08-19 15:00:00' | X14: 13 | Y14: A0013_2026_10_03_22_00_00 | Z14: A0013 | AA14: PL7-3 | AB14: Sản xuất | AC14: null | AD14: null | AE14: null | AF14: null | AG14: null | AH14: Chưa cập nhật | AI14: 0 | AJ14: Ca 1 | AK14: 2026-10-03 | AL14: 2026-10-03 22:00:00 | AM14: Rolled | AN14: null | AO14: Chưa cập nhật | AP14: null | AQ14: Thất bại | AR14: Chưa cập nhật | AS14: 2026-10-03 22:00:00 | AT14: ="(" & X14 & ", '" & Y14 & "', '" & Z14 & "', '" & AA14 & "', '" & AB14 & "', " & AC14 & ", "&AD14&", "&AE14 &", " & AF14 & ", " & AG14 & ", '" & AH14 & "', " & AI14 & ", '" & AJ14 & "', '" & AK14 & "', '" & AL14 & "', '" & AM14 & "', " & AN14 & ", '" & AO14 & "', " & AP14 & ", '" & AQ14 & "', '" & AR14 & "', '" & AS14 & "')," -> (13, 'A0013_2026_10_03_22_00_00', 'A0013', 'PL7-3', 'Sản xuất', null, null, null, null, null, 'Chưa cập nhật', 0, 'Ca 1', '2026-10-03', '2026-10-03 22:00:00', 'Rolled', null, 'Chưa cập nhật', null, 'Thất bại', 'Chưa cập nhật', '2026-10-03 22:00:00'),
... A3001: (3000, 'C1000_2026_10_03_22_00_00', 'C1000', 'PL4-7 (TU08~)', 'Sản xuất', null, null, null, null, null, 'Chưa cập nhật', 0, 'Ca 1', '2026-10-03', '2026-10-03 22:00:00', 'Rolled', null, 'Chưa cập nhật', null, 'Thất bại', 'Chưa cập nhật', '2026-10-03 22:00:00'), | B3001: =MID(A3001,2,LEN(A3001)-3) -> 3000, 'C1000_2026_10_03_22_00_00', 'C1000', 'PL4-7 (TU08~)', 'Sản xuất', null, null, null, null, null, 'Chưa cập nhật', 0, 'Ca 1', '2026-10-03', '2026-10-03 22:00:00', 'Rolled', null, 'Chưa cập nhật', null, 'Thất bại', 'Chưa cập nhật', '2026-10-03 22:00:00' | C3001: 3000 | D3001: 'C1000_2026_08_19_15_00_00' | E3001: 'C1000' | F3001: 'PL4-7 (TU08~)' | G3001: 'Sản xuất' | H3001: null | I3001: null | J3001: null | K3001: 'Chưa cập nhật' | L3001: 0 | M3001: 'Ca 3000' | N3001: '2026-08-19' | O3001: '2026-08-19 15:00:00' | P3001: 'Rolled' | Q3001: null | R3001: 'Chưa cập nhật' | S3001: null | T3001: 'Thất bại' | U3001: 'Chưa cập nhật' | V3001: '2026-08-19 15:00:00' | X3001: 3000 | Y3001: C1000_2026_10_03_22_00_00 | Z3001: C1000 | AA3001: PL4-7 (TU08~) | AB3001: Sản xuất | AC3001: null | AD3001: null | AE3001: null | AF3001: null | AG3001: null | AH3001: Chưa cập nhật | AI3001: 0 | AJ3001: Ca 1 | AK3001: 2026-10-03 | AL3001: 2026-10-03 22:00:00 | AM3001: Rolled | AN3001: null | AO3001: Chưa cập nhật | AP3001: null | AQ3001: Thất bại | AR3001: Chưa cập nhật | AS3001: 2026-10-03 22:00:00 | AT3001: ="(" & X3001 & ", '" & Y3001 & "', '" & Z3001 & "', '" & AA3001 & "', '" & AB3001 & "', " & AC3001 & ", "&AD3001&", "&AE3001 &", " & AF3001 & ", " & AG3001 & ", '" & AH3001 & "', " & AI3001 & ", '" & AJ3001 & "', '" & AK3001 & "', '" & AL3001 & "', '" & AM3001 & "', " & AN3001 & ", '" & AO3001 & "', " & AP3001 & ", '" & AQ3001 & "', '" & AR3001 & "', '" & AS3001 & "')," -> (3000, 'C1000_2026_10_03_22_00_00', 'C1000', 'PL4-7 (TU08~)', 'Sản xuất', null, null, null, null, null, 'Chưa cập nhật', 0, 'Ca 1', '2026-10-03', '2026-10-03 22:00:00', 'Rolled', null, 'Chưa cập nhật', null, 'Thất bại', 'Chưa cập nhật', '2026-10-03 22:00:00'),

Sheet rack_list
A1: id | B1: rack_code | D1: Upload to SQL
A2: 1 | B2: Rack_B021_01 | D2: ="("&A2&", "&"'"&B2&"'"&")"&"," -> (1, 'Rack_B021_01'),
A3: 2 | B3: Rack_B021_02 | D3: ="("&A3&", "&"'"&B3&"'"&")"&"," -> (2, 'Rack_B021_02'),
A4: 3 | B4: Rack_B021_03 | D4: ="("&A4&", "&"'"&B4&"'"&")"&"," -> (3, 'Rack_B021_03'),
A5: 4 | B5: Rack_B021_04 | D5: ="("&A5&", "&"'"&B5&"'"&")"&"," -> (4, 'Rack_B021_04'),
A6: 5 | B6: Rack_B021_05 | D6: ="("&A6&", "&"'"&B6&"'"&")"&"," -> (5, 'Rack_B021_05'),
A7: 6 | B7: Rack_B021_06 | D7: ="("&A7&", "&"'"&B7&"'"&")"&"," -> (6, 'Rack_B021_06'),
A8: 7 | B8: Rack_B021_07 | D8: ="("&A8&", "&"'"&B8&"'"&")"&"," -> (7, 'Rack_B021_07'),
A9: 8 | B9: Rack_B021_08 | D9: ="("&A9&", "&"'"&B9&"'"&")"&"," -> (8, 'Rack_B021_08'),
A10: 9 | B10: Rack_B021_09 | D10: ="("&A10&", "&"'"&B10&"'"&")"&"," -> (9, 'Rack_B021_09'),
A11: 10 | B11: Rack_B021_10 | D11: ="("&A11&", "&"'"&B11&"'"&")"&"," -> (10, 'Rack_B021_10'),
A12: 11 | B12: Rack_B021_11 | D12: ="("&A12&", "&"'"&B12&"'"&")"&"," -> (11, 'Rack_B021_11'),
A13: 12 | B13: Rack_B021_12 | D13: ="("&A13&", "&"'"&B13&"'"&")"&"," -> (12, 'Rack_B021_12'),
... A401: 400 | B401: Rack_B032_100 | D401: ="("&A401&", "&"'"&B401&"'"&")"&"," -> (400, 'Rack_B032_100'),

Sheet day_list
A1: UPLOAD TO SQL | C1: id | D1: code | E1: day
A2: {=_xlfn.UNIQUE(F2:F32)} -> (1, 'A', '1'), | C2: 1 | D2: A | E2: 1 | F2: ="("&C2&", "&"'"&D2&"'"&", "&"'"&E2&"'"&")"&"," -> (1, 'A', '1'),
A3: (2, 'B', '2'), | C3: 2 | D3: B | E3: 2 | F3: ="("&C3&", "&"'"&D3&"'"&", "&"'"&E3&"'"&")"&"," -> (2, 'B', '2'),
A4: (3, 'C', '3'), | C4: 3 | D4: C | E4: 3 | F4: ="("&C4&", "&"'"&D4&"'"&", "&"'"&E4&"'"&")"&"," -> (3, 'C', '3'),
A5: (4, 'D', '4'), | C5: 4 | D5: D | E5: 4 | F5: ="("&C5&", "&"'"&D5&"'"&", "&"'"&E5&"'"&")"&"," -> (4, 'D', '4'),
A6: (5, 'E', '5'), | C6: 5 | D6: E | E6: 5 | F6: ="("&C6&", "&"'"&D6&"'"&", "&"'"&E6&"'"&")"&"," -> (5, 'E', '5'),
A7: (6, 'F', '6'), | C7: 6 | D7: F | E7: 6 | F7: ="("&C7&", "&"'"&D7&"'"&", "&"'"&E7&"'"&")"&"," -> (6, 'F', '6'),
A8: (7, 'G', '7'), | C8: 7 | D8: G | E8: 7 | F8: ="("&C8&", "&"'"&D8&"'"&", "&"'"&E8&"'"&")"&"," -> (7, 'G', '7'),
A9: (8, 'H', '8'), | C9: 8 | D9: H | E9: 8 | F9: ="("&C9&", "&"'"&D9&"'"&", "&"'"&E9&"'"&")"&"," -> (8, 'H', '8'),
A10: (9, 'i', '9'), | C10: 9 | D10: i | E10: 9 | F10: ="("&C10&", "&"'"&D10&"'"&", "&"'"&E10&"'"&")"&"," -> (9, 'i', '9'),
A11: (10, 'J', '10'), | C11: 10 | D11: J | E11: 10 | F11: ="("&C11&", "&"'"&D11&"'"&", "&"'"&E11&"'"&")"&"," -> (10, 'J', '10'),
A12: (11, 'K', '11'), | C12: 11 | D12: K | E12: 11 | F12: ="("&C12&", "&"'"&D12&"'"&", "&"'"&E12&"'"&")"&"," -> (11, 'K', '11'),
A13: (12, 'L', '12'), | C13: 12 | D13: L | E13: 12 | F13: ="("&C13&", "&"'"&D13&"'"&", "&"'"&E13&"'"&")"&"," -> (12, 'L', '12'),
A14: (13, 'M', '13'), | C14: 13 | D14: M | E14: 13 | F14: ="("&C14&", "&"'"&D14&"'"&", "&"'"&E14&"'"&")"&"," -> (13, 'M', '13'),
... A32: (31, 'h', '31'), | C32: 31 | D32: h | E32: 31 | F32: ="("&C32&", "&"'"&D32&"'"&", "&"'"&E32&"'"&")"&"," -> (31, 'h', '31'),

Sheet month_list
A1: UPLOAD TO SQL | C1: id | D1: code | E1: month
A2: {=_xlfn.UNIQUE(F2:F13)} -> (1, 'o', 1), | C2: 1 | D2: o | E2: 1 | F2: ="("&C2&", "&"'"&D2&"'"&", "&E2&")"&"," -> (1, 'o', 1),
A3: (2, 'P', 2), | C3: 2 | D3: P | E3: 2 | F3: ="("&C3&", "&"'"&D3&"'"&", "&E3&")"&"," -> (2, 'P', 2),
A4: (3, 'Q', 3), | C4: 3 | D4: Q | E4: 3 | F4: ="("&C4&", "&"'"&D4&"'"&", "&E4&")"&"," -> (3, 'Q', 3),
A5: (4, 'R', 4), | C5: 4 | D5: R | E5: 4 | F5: ="("&C5&", "&"'"&D5&"'"&", "&E5&")"&"," -> (4, 'R', 4),
A6: (5, 'S', 5), | C6: 5 | D6: S | E6: 5 | F6: ="("&C6&", "&"'"&D6&"'"&", "&E6&")"&"," -> (5, 'S', 5),
A7: (6, 'T', 6), | C7: 6 | D7: T | E7: 6 | F7: ="("&C7&", "&"'"&D7&"'"&", "&E7&")"&"," -> (6, 'T', 6),
A8: (7, 'U', 7), | C8: 7 | D8: U | E8: 7 | F8: ="("&C8&", "&"'"&D8&"'"&", "&E8&")"&"," -> (7, 'U', 7),
A9: (8, 'V', 8), | C9: 8 | D9: V | E9: 8 | F9: ="("&C9&", "&"'"&D9&"'"&", "&E9&")"&"," -> (8, 'V', 8),
A10: (9, 'W', 9), | C10: 9 | D10: W | E10: 9 | F10: ="("&C10&", "&"'"&D10&"'"&", "&E10&")"&"," -> (9, 'W', 9),
A11: (10, 'X', 10), | C11: 10 | D11: X | E11: 10 | F11: ="("&C11&", "&"'"&D11&"'"&", "&E11&")"&"," -> (10, 'X', 10),
A12: (11, 'y', 11), | C12: 11 | D12: y | E12: 11 | F12: ="("&C12&", "&"'"&D12&"'"&", "&E12&")"&"," -> (11, 'y', 11),
A13: (12, 'Z', 12), | C13: 12 | D13: Z | E13: 12 | F13: ="("&C13&", "&"'"&D13&"'"&", "&E13&")"&"," -> (12, 'Z', 12),

Sheet year_list
A1: UPLOAD TO SQL | C1: id | D1: code | E1: year
A2: {=_xlfn.UNIQUE(F2:F13)} -> (1, 'V', 2017), | C2: 1 | D2: V | E2: 2017 | F2: ="("&C2&", "&"'"&D2&"'"&", "&E2&")"&"," -> (1, 'V', 2017),
A3: (2, 'W', 2018), | C3: 2 | D3: W | E3: 2018 | F3: ="("&C3&", "&"'"&D3&"'"&", "&E3&")"&"," -> (2, 'W', 2018),
A4: (3, 'X', 2019), | C4: 3 | D4: X | E4: 2019 | F4: ="("&C4&", "&"'"&D4&"'"&", "&E4&")"&"," -> (3, 'X', 2019),
A5: (4, 'y', 2020), | C5: 4 | D5: y | E5: 2020 | F5: ="("&C5&", "&"'"&D5&"'"&", "&E5&")"&"," -> (4, 'y', 2020),
A6: (5, 'Z', 2021), | C6: 5 | D6: Z | E6: 2021 | F6: ="("&C6&", "&"'"&D6&"'"&", "&E6&")"&"," -> (5, 'Z', 2021),
A7: (6, 'A', 2022), | C7: 6 | D7: A | E7: 2022 | F7: ="("&C7&", "&"'"&D7&"'"&", "&E7&")"&"," -> (6, 'A', 2022),
A8: (7, 'B', 2023), | C8: 7 | D8: B | E8: 2023 | F8: ="("&C8&", "&"'"&D8&"'"&", "&E8&")"&"," -> (7, 'B', 2023),
A9: (8, 'C', 2024), | C9: 8 | D9: C | E9: 2024 | F9: ="("&C9&", "&"'"&D9&"'"&", "&E9&")"&"," -> (8, 'C', 2024),
A10: (9, 'D', 2025), | C10: 9 | D10: D | E10: 2025 | F10: ="("&C10&", "&"'"&D10&"'"&", "&E10&")"&"," -> (9, 'D', 2025),
A11: (10, 'E', 2026), | C11: 10 | D11: E | E11: 2026 | F11: ="("&C11&", "&"'"&D11&"'"&", "&E11&")"&"," -> (10, 'E', 2026),
A12: (11, 'F', 2027), | C12: 11 | D12: F | E12: 2027 | F12: ="("&C12&", "&"'"&D12&"'"&", "&E12&")"&"," -> (11, 'F', 2027),
A13: (12, 'G', 2028), | C13: 12 | D13: G | E13: 2028 | F13: ="("&C13&", "&"'"&D13&"'"&", "&E13&")"&"," -> (12, 'G', 2028),

Sheet employee_list
A1: UPLOAD TO SQL | B1: id | C1: employee_code | D1: employee_name | E1: role | F1: username | G1: password | H1: is_active | I1: is_first_login | J1: updated_time | K1: Thời điểm cập nhật (Quy ước)
A2: {=_xlfn.UNIQUE(M2:M136)} -> (1, '01510036', 'Nguyễn Thành Thân', 'admin', '01510036', '123', 1, 1, '2026-10-03 22:00:00'), | B2: 1 | C2: 01510036 | D2: Nguyễn Thành Thân | E2: admin | F2: =C2 -> 01510036 | G2: 123 | H2: 1 | I2: 1 | J2: 2026-10-03 22:00:00 | K2: 2026-10-03 22:00:00 | M2: ="("&B2&", '"&C2&"', '"&D2&"', '"&E2&"', '"&F2&"', '"&G2&"', "&H2&", "&I2&", '"&TEXT(J2,"yyyy-mm-dd hh:mm:ss")&"')," -> (1, '01510036', 'Nguyễn Thành Thân', 'admin', '01510036', '123', 1, 1, '2026-10-03 22:00:00'),
A3: (2, '01910698', 'Nguyễn Thị Hiền', 'admin', '01910698', '123', 1, 1, '2026-10-03 22:00:00'), | B3: 2 | C3: 01910698 | D3: Nguyễn Thị Hiền | E3: admin | F3: =C3 -> 01910698 | G3: 123 | H3: 1 | I3: 1 | J3: 2026-10-03 22:00:00 | K3: 2026-03-11 15:00:00 | M3: ="("&B3&", '"&C3&"', '"&D3&"', '"&E3&"', '"&F3&"', '"&G3&"', "&H3&", "&I3&", '"&TEXT(J3,"yyyy-mm-dd hh:mm:ss")&"')," -> (2, '01910698', 'Nguyễn Thị Hiền', 'admin', '01910698', '123', 1, 1, '2026-10-03 22:00:00'),
A4: (3, '01911022', 'Kiều Minh Thiện', 'admin', '01911022', '123', 1, 1, '2026-10-03 22:00:00'), | B4: 3 | C4: 01911022 | D4: Kiều Minh Thiện | E4: admin | F4: =C4 -> 01911022 | G4: 123 | H4: 1 | I4: 1 | J4: 2026-10-03 22:00:00 | K4: 2026-03-11 15:00:00 | M4: ="("&B4&", '"&C4&"', '"&D4&"', '"&E4&"', '"&F4&"', '"&G4&"', "&H4&", "&I4&", '"&TEXT(J4,"yyyy-mm-dd hh:mm:ss")&"')," -> (3, '01911022', 'Kiều Minh Thiện', 'admin', '01911022', '123', 1, 1, '2026-10-03 22:00:00'),
A5: (4, '02114273', 'Thân Trọng Tuấn', 'admin', '02114273', '123', 1, 1, '2026-10-03 22:00:00'), | B5: 4 | C5: 02114273 | D5: Thân Trọng Tuấn | E5: admin | F5: =C5 -> 02114273 | G5: 123 | H5: 1 | I5: 1 | J5: 2026-10-03 22:00:00 | K5: 2026-03-11 15:00:00 | M5: ="("&B5&", '"&C5&"', '"&D5&"', '"&E5&"', '"&F5&"', '"&G5&"', "&H5&", "&I5&", '"&TEXT(J5,"yyyy-mm-dd hh:mm:ss")&"')," -> (4, '02114273', 'Thân Trọng Tuấn', 'admin', '02114273', '123', 1, 1, '2026-10-03 22:00:00'),
A6: (5, '02114811', 'Nguyễn Chấn Huy', 'admin', '02114811', '123', 1, 1, '2026-10-03 22:00:00'), | B6: 5 | C6: 02114811 | D6: Nguyễn Chấn Huy | E6: admin | F6: =C6 -> 02114811 | G6: 123 | H6: 1 | I6: 1 | J6: 2026-10-03 22:00:00 | K6: 2026-03-11 15:00:00 | M6: ="("&B6&", '"&C6&"', '"&D6&"', '"&E6&"', '"&F6&"', '"&G6&"', "&H6&", "&I6&", '"&TEXT(J6,"yyyy-mm-dd hh:mm:ss")&"')," -> (5, '02114811', 'Nguyễn Chấn Huy', 'admin', '02114811', '123', 1, 1, '2026-10-03 22:00:00'),
A7: (6, '01920507', 'Hồ Thị Mỹ', 'admin', '01920507', '123', 1, 1, '2026-10-03 22:00:00'), | B7: 6 | C7: 01920507 | D7: Hồ Thị Mỹ | E7: admin | F7: =C7 -> 01920507 | G7: 123 | H7: 1 | I7: 1 | J7: 2026-10-03 22:00:00 | K7: 2026-03-11 15:00:00 | M7: ="("&B7&", '"&C7&"', '"&D7&"', '"&E7&"', '"&F7&"', '"&G7&"', "&H7&", "&I7&", '"&TEXT(J7,"yyyy-mm-dd hh:mm:ss")&"')," -> (6, '01920507', 'Hồ Thị Mỹ', 'admin', '01920507', '123', 1, 1, '2026-10-03 22:00:00'),
A8: (7, '02411884', 'Phan Đình Lâm', 'admin', '02411884', '123', 1, 1, '2026-10-03 22:00:00'), | B8: 7 | C8: 02411884 | D8: Phan Đình Lâm | E8: admin | F8: =C8 -> 02411884 | G8: 123 | H8: 1 | I8: 1 | J8: 2026-10-03 22:00:00 | K8: 2026-03-11 15:00:00 | M8: ="("&B8&", '"&C8&"', '"&D8&"', '"&E8&"', '"&F8&"', '"&G8&"', "&H8&", "&I8&", '"&TEXT(J8,"yyyy-mm-dd hh:mm:ss")&"')," -> (7, '02411884', 'Phan Đình Lâm', 'admin', '02411884', '123', 1, 1, '2026-10-03 22:00:00'),
A9: (8, '02516134', 'Ngô Xuân Nghĩa', 'admin', '02516134', '123', 1, 1, '2026-10-03 22:00:00'), | B9: 8 | C9: 02516134 | D9: Ngô Xuân Nghĩa | E9: admin | F9: =C9 -> 02516134 | G9: 123 | H9: 1 | I9: 1 | J9: 2026-10-03 22:00:00 | K9: 2026-03-11 15:00:00 | M9: ="("&B9&", '"&C9&"', '"&D9&"', '"&E9&"', '"&F9&"', '"&G9&"', "&H9&", "&I9&", '"&TEXT(J9,"yyyy-mm-dd hh:mm:ss")&"')," -> (8, '02516134', 'Ngô Xuân Nghĩa', 'admin', '02516134', '123', 1, 1, '2026-10-03 22:00:00'),
A10: (9, '02519007', 'Ninh Quang Trường', 'admin', '02519007', '123', 1, 1, '2026-10-03 22:00:00'), | B10: 9 | C10: 02519007 | D10: Ninh Quang Trường | E10: admin | F10: =C10 -> 02519007 | G10: 123 | H10: 1 | I10: 1 | J10: 2026-10-03 22:00:00 | K10: 2026-03-11 15:00:00 | M10: ="("&B10&", '"&C10&"', '"&D10&"', '"&E10&"', '"&F10&"', '"&G10&"', "&H10&", "&I10&", '"&TEXT(J10,"yyyy-mm-dd hh:mm:ss")&"')," -> (9, '02519007', 'Ninh Quang Trường', 'admin', '02519007', '123', 1, 1, '2026-10-03 22:00:00'),
A11: (10, '02619486', 'Nguyễn Đức Huy', 'admin', '02619486', '123', 1, 1, '2026-10-03 22:00:00'), | B11: 10 | C11: 02619486 | D11: Nguyễn Đức Huy | E11: admin | F11: =C11 -> 02619486 | G11: 123 | H11: 1 | I11: 1 | J11: 2026-10-03 22:00:00 | K11: 2026-03-11 15:00:00 | M11: ="("&B11&", '"&C11&"', '"&D11&"', '"&E11&"', '"&F11&"', '"&G11&"', "&H11&", "&I11&", '"&TEXT(J11,"yyyy-mm-dd hh:mm:ss")&"')," -> (10, '02619486', 'Nguyễn Đức Huy', 'admin', '02619486', '123', 1, 1, '2026-10-03 22:00:00'),
A12: (11, '02317843', 'Đinh Hoàng Phúc', 'admin', '02317843', '123', 1, 1, '2026-10-03 22:00:00'), | B12: 11 | C12: 02317843 | D12: Đinh Hoàng Phúc | E12: admin | F12: =C12 -> 02317843 | G12: 123 | H12: 1 | I12: 1 | J12: 2026-10-03 22:00:00 | K12: 2026-03-11 15:00:00 | M12: ="("&B12&", '"&C12&"', '"&D12&"', '"&E12&"', '"&F12&"', '"&G12&"', "&H12&", "&I12&", '"&TEXT(J12,"yyyy-mm-dd hh:mm:ss")&"')," -> (11, '02317843', 'Đinh Hoàng Phúc', 'admin', '02317843', '123', 1, 1, '2026-10-03 22:00:00'),
A13: (12, '01920598', 'Trịnh Minh Thiện', 'admin', '01920598', '123', 1, 1, '2026-10-03 22:00:00'), | B13: 12 | C13: 01920598 | D13: Trịnh Minh Thiện | E13: admin | F13: =C13 -> 01920598 | G13: 123 | H13: 1 | I13: 1 | J13: 2026-10-03 22:00:00 | K13: 2026-03-11 15:00:00 | M13: ="("&B13&", '"&C13&"', '"&D13&"', '"&E13&"', '"&F13&"', '"&G13&"', "&H13&", "&I13&", '"&TEXT(J13,"yyyy-mm-dd hh:mm:ss")&"')," -> (12, '01920598', 'Trịnh Minh Thiện', 'admin', '01920598', '123', 1, 1, '2026-10-03 22:00:00'),
A14: (13, '01920871', 'Xa Minh Hiếu', 'admin', '01920871', '123', 1, 1, '2026-10-03 22:00:00'), | B14: 13 | C14: 01920871 | D14: Xa Minh Hiếu | E14: admin | F14: =C14 -> 01920871 | G14: 123 | H14: 1 | I14: 1 | J14: 2026-10-03 22:00:00 | K14: 2026-03-11 15:00:00 | M14: ="("&B14&", '"&C14&"', '"&D14&"', '"&E14&"', '"&F14&"', '"&G14&"', "&H14&", "&I14&", '"&TEXT(J14,"yyyy-mm-dd hh:mm:ss")&"')," -> (13, '01920871', 'Xa Minh Hiếu', 'admin', '01920871', '123', 1, 1, '2026-10-03 22:00:00'),
... A136: (135, '02649238', 'Huỳnh Thị Kim Hậu', 'winding', '02649238', '123', 1, 1, '2026-10-03 22:00:00'), | B136: 135 | C136: 02649238 | D136: Huỳnh Thị Kim Hậu | E136: winding | F136: =C136 -> 02649238 | G136: 123 | H136: 1 | I136: 1 | J136: 2026-10-03 22:00:00 | K136: 2026-03-11 15:00:00 | M136: ="("&B136&", '"&C136&"', '"&D136&"', '"&E136&"', '"&F136&"', '"&G136&"', "&H136&", "&I136&", '"&TEXT(J136,"yyyy-mm-dd hh:mm:ss")&"')," -> (135, '02649238', 'Huỳnh Thị Kim Hậu', 'winding', '02649238', '123', 1, 1, '2026-10-03 22:00:00'),

Sheet role
A1: STT | B1: MSNV | C1: Họ tên | D1: Costcenter mới | E1: role | G1: {=_xlfn.UNIQUE(D2:D138)} -> A00536 | H1: Assistant manager
A2: 1 | B2: 01510036 | C2: Nguyễn Thành Thân | D2: A00536 | E2: =VLOOKUP(B2,employee_list!C:E,3,FALSE) -> admin | G2: A00791 | H2: Thiết bị đùn
A3: 2 | B3: 01910698 | C3: Nguyễn Thị Hiền | D3: A00536 | E3: =VLOOKUP(B3,employee_list!C:E,3,FALSE) -> admin | G3: A00564 | H3: Quản lý đùn TU
A4: 3 | B4: 01911022 | C4: Kiều Minh Thiện | D4: A00791 | E4: =VLOOKUP(B4,employee_list!C:E,3,FALSE) -> admin | G4: A00565 | H4: Quản lý cuộn TU
A5: 4 | B5: 02114273 | C5: Thân Trọng Tuấn | D5: A00564 | E5: =VLOOKUP(B5,employee_list!C:E,3,FALSE) -> admin | G5: A00340 | H5: Văn phòng
A6: 5 | B6: 02114811 | C6: Nguyễn Chấn Huy | D6: A00565 | E6: =VLOOKUP(B6,employee_list!C:E,3,FALSE) -> admin | G6: A00853 | H6: Quản lý đùn T
A7: 6 | B7: 01920507 | C7: Hồ Thị Mỹ | D7: A00340 | E7: =VLOOKUP(B7,employee_list!C:E,3,FALSE) -> admin | G7: A00855 | H7: Quản lý cuộn T
A8: 7 | B8: 02411884 | C8: Phan Đình Lâm | D8: A00340 | E8: =VLOOKUP(B8,employee_list!C:E,3,FALSE) -> admin | G8: A00792 | H8: QC
A9: 8 | B9: 02516134 | C9: Ngô Xuân Nghĩa | D9: A00340 | E9: =VLOOKUP(B9,employee_list!C:E,3,FALSE) -> admin | G9: A00330 | H9: Đùn TU
A10: 9 | B10: 02519007 | C10: Ninh Quang Trường | D10: A00340 | E10: =VLOOKUP(B10,employee_list!C:E,3,FALSE) -> admin | G10: A00852 | H10: Đùn T
A11: 10 | B11: 02619486 | C11: Nguyễn Đức Huy | D11: A00340 | E11: =VLOOKUP(B11,employee_list!C:E,3,FALSE) -> admin | G11: A00442 | H11: Nghiền
A12: 11 | B12: 02317843 | C12: Đinh Hoàng Phúc | D12: A00853 | E12: =VLOOKUP(B12,employee_list!C:E,3,FALSE) -> admin | G12: A00430 | H12: Cuộn TU
A13: 12 | B13: 01920598 | C13: Trịnh Minh Thiện | D13: A00791 | E13: =VLOOKUP(B13,employee_list!C:E,3,FALSE) -> admin | G13: A00854 | H13: Cuộn T
A14: 13 | B14: 01920871 | C14: Xa Minh Hiếu | D14: A00791 | E14: =VLOOKUP(B14,employee_list!C:E,3,FALSE) -> admin
A15: 14 | B15: 02216809 | C15: Nguyễn Bá Nhân Hậu | D15: A00855 | E15: =VLOOKUP(B15,employee_list!C:E,3,FALSE) -> admin
A16: 15 | B16: 01920172 | C16: Võ Thị Mỹ | D16: A00792 | E16: =VLOOKUP(B16,employee_list!C:E,3,FALSE) -> qc
A17: 16 | B17: 01920525 | C17: Lương Thị Vân | D17: A00792 | E17: =VLOOKUP(B17,employee_list!C:E,3,FALSE) -> qc
A18: 17 | B18: 02125543 | C18: Đinh Thị Huyền Trang | D18: A00792 | E18: =VLOOKUP(B18,employee_list!C:E,3,FALSE) -> qc
A19: 18 | B19: 02649247 | C19: Trương Cẩm Mừng | D19: A00792 | E19: =VLOOKUP(B19,employee_list!C:E,3,FALSE) -> qc
A20: 19 | B20: 02649256 | C20: Nguyễn Thị Thu | D20: A00792 | E20: =VLOOKUP(B20,employee_list!C:E,3,FALSE) -> qc
A21: 20 | B21: 01920589 | C21: Nguyễn Ngọc Thiện | D21: A00330 | E21: =VLOOKUP(B21,employee_list!C:E,3,FALSE) -> extrusion
A22: 21 | B22: 01920668 | C22: Hà Viết Thế Thiện | D22: A00852 | E22: =VLOOKUP(B22,employee_list!C:E,3,FALSE) -> extrusion
A23: 22 | B23: 01920862 | C23: Nguyễn Khắc Kiên | D23: A00330 | E23: =VLOOKUP(B23,employee_list!C:E,3,FALSE) -> extrusion
A24: 23 | B24: 01921551 | C24: Trương Quang Nghĩa | D24: A00330 | E24: =VLOOKUP(B24,employee_list!C:E,3,FALSE) -> extrusion
A25: 24 | B25: 01921560 | C25: Trần Quang Hiệu | D25: A00330 | E25: =VLOOKUP(B25,employee_list!C:E,3,FALSE) -> extrusion
... A75: 74 | B75: 01920552 | C75: Lê Thị Phượng Hằng | D75: A00430 | E75: =VLOOKUP(B75,employee_list!C:E,3,FALSE) -> winding
A76: 75 | B76: 1921108 | C76: Dương Thị Mỹ Hà | D76: A00430 | E76: =VLOOKUP(B76,employee_list!C:E,3,FALSE) -> #N/A
A77: 76 | B77: 01921603 | C77: Nguyễn Trần Anh Thư | D77: A00430 | E77: =VLOOKUP(B77,employee_list!C:E,3,FALSE) -> winding
A78: 77 | B78: 01921700 | C78: Trần Thị Minh Phương | D78: A00430 | E78: =VLOOKUP(B78,employee_list!C:E,3,FALSE) -> winding
A79: 78 | B79: 01921694 | C79: Tạ Tuyền Phong | D79: A00430 | E79: =VLOOKUP(B79,employee_list!C:E,3,FALSE) -> winding
A80: 79 | B80: 01921764 | C80: Nguyễn Trung Nhân | D80: A00430 | E80: =VLOOKUP(B80,employee_list!C:E,3,FALSE) -> winding
A81: 80 | B81: 02021496 | C81: Nguyễn Việt Thắng | D81: A00430 | E81: =VLOOKUP(B81,employee_list!C:E,3,FALSE) -> winding
A82: 81 | B82: 02021502 | C82: Phan Thị Huệ | D82: A00430 | E82: =VLOOKUP(B82,employee_list!C:E,3,FALSE) -> winding
A83: 82 | B83: 02021511 | C83: Võ Thị Vân Anh | D83: A00430 | E83: =VLOOKUP(B83,employee_list!C:E,3,FALSE) -> winding
A84: 83 | B84: 02021788 | C84: Nguyễn Thị Cẩm Tú | D84: A00430 | E84: =VLOOKUP(B84,employee_list!C:E,3,FALSE) -> winding
A85: 84 | B85: 02021797 | C85: Hoàng Thị Yên | D85: A00430 | E85: =VLOOKUP(B85,employee_list!C:E,3,FALSE) -> winding
A86: 85 | B86: 02021803 | C86: Nguyễn Thị Yến Văn | D86: A00854 | E86: =VLOOKUP(B86,employee_list!C:E,3,FALSE) -> winding
A87: 86 | B87: 02121398 | C87: Lê Đại Dương | D87: A00430 | E87: =VLOOKUP(B87,employee_list!C:E,3,FALSE) -> winding
A88: 87 | B88: 02121714 | C88: Lê Hải | D88: A00430 | E88: =VLOOKUP(B88,employee_list!C:E,3,FALSE) -> winding
... A138: 137 | B138: 02649238 | C138: Huỳnh Thị Kim Hậu | D138: A00430 | E138: =VLOOKUP(B138,employee_list!C:E,3,FALSE) -> winding

Sheet extrusion_machine_list
A1: UPLOAD TO SQL | C1: id | D1: machine_number | E1: machine_code | F1: machine_name
A2: {=_xlfn.UNIQUE(G2:G27)} -> (1, 1, '1', 'PL13'), | C2: 1 | D2: 1 | E2: 1 | F2: PL13 | G2: ="("&C2&", "&D2&", "&"'"&E2&"'"&", "&"'"&F2&"'"&")"&"," -> (1, 1, '1', 'PL13'),
A3: (2, 2, '2', 'PL12'), | C3: 2 | D3: 2 | E3: 2 | F3: PL12 | G3: ="("&C3&", "&D3&", "&"'"&E3&"'"&", "&"'"&F3&"'"&")"&"," -> (2, 2, '2', 'PL12'),
A4: (3, 3, '3', 'PL01'), | C4: 3 | D4: 3 | E4: 3 | F4: PL01 | G4: ="("&C4&", "&D4&", "&"'"&E4&"'"&", "&"'"&F4&"'"&")"&"," -> (3, 3, '3', 'PL01'),
A5: (4, 4, '4', 'PL02'), | C5: 4 | D5: 4 | E5: 4 | F5: PL02 | G5: ="("&C5&", "&D5&", "&"'"&E5&"'"&", "&"'"&F5&"'"&")"&"," -> (4, 4, '4', 'PL02'),
A6: (5, 5, '5', 'PL03'), | C6: 5 | D6: 5 | E6: 5 | F6: PL03 | G6: ="("&C6&", "&D6&", "&"'"&E6&"'"&", "&"'"&F6&"'"&")"&"," -> (5, 5, '5', 'PL03'),
A7: (6, 6, '6', 'PL04'), | C7: 6 | D7: 6 | E7: 6 | F7: PL04 | G7: ="("&C7&", "&D7&", "&"'"&E7&"'"&", "&"'"&F7&"'"&")"&"," -> (6, 6, '6', 'PL04'),
A8: (7, 7, '7', 'PL05'), | C8: 7 | D8: 7 | E8: 7 | F8: PL05 | G8: ="("&C8&", "&D8&", "&"'"&E8&"'"&", "&"'"&F8&"'"&")"&"," -> (7, 7, '7', 'PL05'),
A9: (8, 8, '8', 'PL06'), | C9: 8 | D9: 8 | E9: 8 | F9: PL06 | G9: ="("&C9&", "&D9&", "&"'"&E9&"'"&", "&"'"&F9&"'"&")"&"," -> (8, 8, '8', 'PL06'),
A10: (9, 9, '9', 'PL07'), | C10: 9 | D10: 9 | E10: 9 | F10: PL07 | G10: ="("&C10&", "&D10&", "&"'"&E10&"'"&", "&"'"&F10&"'"&")"&"," -> (9, 9, '9', 'PL07'),
A11: (10, 10, 'A', 'PL08'), | C11: 10 | D11: 10 | E11: A | F11: PL08 | G11: ="("&C11&", "&D11&", "&"'"&E11&"'"&", "&"'"&F11&"'"&")"&"," -> (10, 10, 'A', 'PL08'),
A12: (11, 11, 'B', 'PL09'), | C12: 11 | D12: 11 | E12: B | F12: PL09 | G12: ="("&C12&", "&D12&", "&"'"&E12&"'"&", "&"'"&F12&"'"&")"&"," -> (11, 11, 'B', 'PL09'),
A13: (12, 12, 'C', 'PL10'), | C13: 12 | D13: 12 | E13: C | F13: PL10 | G13: ="("&C13&", "&D13&", "&"'"&E13&"'"&", "&"'"&F13&"'"&")"&"," -> (12, 12, 'C', 'PL10'),
A14: (13, 13, 'D', 'PL11'), | C14: 13 | D14: 13 | E14: D | F14: PL11 | G14: ="("&C14&", "&D14&", "&"'"&E14&"'"&", "&"'"&F14&"'"&")"&"," -> (13, 13, 'D', 'PL11'),
... A27: (26, 26, 'Q', 'PL26'), | C27: 26 | D27: 26 | E27: Q | F27: PL26 | G27: ="("&C27&", "&D27&", "&"'"&E27&"'"&", "&"'"&F27&"'"&")"&"," -> (26, 26, 'Q', 'PL26'),

Sheet winding_machine_list
A1: UPLOAD TO SQL | C1: id | D1: machine_name
A2: {=_xlfn.UNIQUE(E2:E37)} -> (1, 'ST01'), | C2: 1 | D2: ST01 | E2: ="("&C2&", "&"'"&D2&"'"&")"&"," -> (1, 'ST01'),
A3: (2, 'ST02'), | C3: 2 | D3: ST02 | E3: ="("&C3&", "&"'"&D3&"'"&")"&"," -> (2, 'ST02'),
A4: (3, 'ST03'), | C4: 3 | D4: ST03 | E4: ="("&C4&", "&"'"&D4&"'"&")"&"," -> (3, 'ST03'),
A5: (4, 'ST04'), | C5: 4 | D5: ST04 | E5: ="("&C5&", "&"'"&D5&"'"&")"&"," -> (4, 'ST04'),
A6: (5, 'ST05'), | C6: 5 | D6: ST05 | E6: ="("&C6&", "&"'"&D6&"'"&")"&"," -> (5, 'ST05'),
A7: (6, 'ST06'), | C7: 6 | D7: ST06 | E7: ="("&C7&", "&"'"&D7&"'"&")"&"," -> (6, 'ST06'),
A8: (7, 'ST07'), | C8: 7 | D8: ST07 | E8: ="("&C8&", "&"'"&D8&"'"&")"&"," -> (7, 'ST07'),
A9: (8, 'ST08'), | C9: 8 | D9: ST08 | E9: ="("&C9&", "&"'"&D9&"'"&")"&"," -> (8, 'ST08'),
A10: (9, 'ST09'), | C10: 9 | D10: ST09 | E10: ="("&C10&", "&"'"&D10&"'"&")"&"," -> (9, 'ST09'),
A11: (10, 'ST10'), | C11: 10 | D11: ST10 | E11: ="("&C11&", "&"'"&D11&"'"&")"&"," -> (10, 'ST10'),
A12: (11, 'ST11'), | C12: 11 | D12: ST11 | E12: ="("&C12&", "&"'"&D12&"'"&")"&"," -> (11, 'ST11'),
A13: (12, 'ST12'), | C13: 12 | D13: ST12 | E13: ="("&C13&", "&"'"&D13&"'"&")"&"," -> (12, 'ST12'),
A14: (13, 'ST13'), | C14: 13 | D14: ST13 | E14: ="("&C14&", "&"'"&D14&"'"&")"&"," -> (13, 'ST13'),
... A37: (36, 'ST36'), | C37: 36 | D37: ST36 | E37: ="("&C37&", "&"'"&D37&"'"&")"&"," -> (36, 'ST36'),

Sheet material_list
A1: UPLOAD TO SQL | C1: id | D1: brand | E1: code | F1: grinding_time
A2: {=_xlfn.UNIQUE(G2:G14)} -> #NAME? | C2: 1 | D2: BASF | E2: A | F2: 0 | G2: ="("&C2&","&"'"&D2&"'"&", "&"'"&E2&"'"&", "&F2&")"&"," -> (1,'BASF', 'A', 0),
A3: #NAME? | C3: 2 | D3: BASF | E3: B | F3: 1 | G3: ="("&C3&","&"'"&D3&"'"&", "&"'"&E3&"'"&", "&F3&")"&"," -> (2,'BASF', 'B', 1),
A4: #NAME? | C4: 3 | D4: BASF | E4: C | F4: 2 | G4: ="("&C4&","&"'"&D4&"'"&", "&"'"&E4&"'"&", "&F4&")"&"," -> (3,'BASF', 'C', 2),
A5: #NAME? | C5: 4 | D5: DIC Covestro | E5: D | F5: 0 | G5: ="("&C5&","&"'"&D5&"'"&", "&"'"&E5&"'"&", "&F5&")"&"," -> (4,'DIC Covestro', 'D', 0),
A6: #NAME? | C6: 5 | D6: DIC Covestro | E6: E | F6: 1 | G6: ="("&C6&","&"'"&D6&"'"&", "&"'"&E6&"'"&", "&F6&")"&"," -> (5,'DIC Covestro', 'E', 1),
A7: #NAME? | C7: 6 | D7: DIC Covestro | E7: F | F7: 2 | G7: ="("&C7&","&"'"&D7&"'"&", "&"'"&E7&"'"&", "&F7&")"&"," -> (6,'DIC Covestro', 'F', 2),
A8: #NAME? | C8: 7 | D8: Huntsman | E8: G | F8: 0 | G8: ="("&C8&","&"'"&D8&"'"&", "&"'"&E8&"'"&", "&F8&")"&"," -> (7,'Huntsman', 'G', 0),
A9: #NAME? | C9: 8 | D9: Huntsman | E9: H | F9: 1 | G9: ="("&C9&","&"'"&D9&"'"&", "&"'"&E9&"'"&", "&F9&")"&"," -> (8,'Huntsman', 'H', 1),
A10: #NAME? | C10: 9 | D10: Huntsman | E10: i | F10: 2 | G10: ="("&C10&","&"'"&D10&"'"&", "&"'"&E10&"'"&", "&F10&")"&"," -> (9,'Huntsman', 'i', 2),
